Workbook

Sheet README
A1: بخش | B1: توضیح
A2: هدف فایل | B2: دیتاست آموزشی فصل ۳ فرآوری (جدایش مغناطیسی LIMS/WHIMS، فلوتاسیون معکوس، تیکنر، فیلتراسیون و کیک فیلتر) برای آموزش کنترل کیفیت، SPC، موازنه جرم و فلز، و تحلیل داده در Excel، Minitab، Python و Power BI.
A3: مصنوعی بودن داده | B3: تمام داده‌ها مصنوعی، تصادفی اما مهندسی‌شده (seed تکرارپذیر) تولید شده‌اند و روابط واقع‌گرایانه بین متغیرها دارند. این داده‌ها به هیچ وجه داده واقعی کارخانه نیستند و نباید برای ارزیابی عملکرد کارخانه یا تصمیم‌گیری صنعتی استفاده شوند.
A4: دامنه کاربرد آموزشی | B4: آموزش نمودارهای کنترلی (I-MR)، تحلیل قابلیت فرآیند، عیب‌یابی چندمتغیره رخدادها، ساخت داشبورد Power BI، تمرین موازنه جرم/فلز و آموزش محاسبه Yield و Recovery.
A5: تعریف شیت Process_Data | B5: ثبت‌های هر ۲ ساعت به مدت ۳۰ روز (۳۶۰ ردیف): متغیرهای خوراک، LIMS/WHIMS، فلوتاسیون و کیفیت آب. ستون‌های خالی در هر مدار عملیاتی به معنی غیرفعال بودن آن واحد در آن مدار است.
A6: تعریف شیت Dewatering_Balance | B6: هم‌تراز ردیف‌به‌ردیف با Process_Data از طریق Record_ID: متغیرهای تیکنر و فیلتر، جریان‌های خشک، عیارها و KPIهای موازنه با فرمول Excel زنده.
A7: تعریف شیت Calculations | B7: روابط Yield، Recovery و خطاهای موازنه، فرمول‌های Excel قابل کپی برای کل داده، نمونه محاسبه و کنترل‌های منطقی.
A8: تعریف شیت SPC_Sample | B8: زیرمجموعه تمیز ۱۲۰ ردیفه (فقط Quality_Flag=OK) برای نمودار I-MR رطوبت کیک و نمودار کنترل کدورت اورفلو و آهن باطله، به‌همراه Target/LSL/USL آموزشی.
A9: تعریف شیت Dashboard_Data | B9: خلاصه روزانه/شیفت‌بندی ۹۰ ردیفی شاخص‌های کلیدی؛ مناسب مدل ستاره‌ای Power BI با کلید Date+Shift.
A10: تعریف شیت Minitab_Import | B10: نسخه عددی تمیز ۱۲۰ ردیفه بدون ستون متنی، آماده Paste یا Import در Minitab.
A11: نکات Excel | B11: ردیف اول هر شیت Header است؛ از View > Freeze Panes و Data > Filter استفاده کنید. فرمول‌های KPI در شیت Dewatering_Balance زنده‌اند و با تغییر داده به‌روز می‌شوند.
A12: نکات Minitab | B12: ستون‌های شیت Minitab_Import را Copy و در Minitab Paste یا از مسیر File > Import استفاده کنید؛ نام ستون‌ها انگلیسی استاندارد است.
... A16: رفتارهای آموزشی نهفته | B16: شش رخداد علت ویژه در داده تعبیه شده است (افزایش اسلایم، گرفتگی ماتریکس WHIMS، اختلال فلوکولانت/تیکنر، افت وکیوم/گرفتگی پارچه، تغییر کیفیت آب، خطای موازنه آموزشی) بدون ستون Root_Cause؛ کیفیت از روی متغیرها قابل تشخیص است.

Sheet Data_Dictionary
A1: Column | B1: تعریف | C1: واحد | D1: نوع داده | E1: محل اندازه‌گیری | F1: نقش | G1: رابطه مورد انتظار با خروجی‌ها
A2: Record_ID | B2: شناسه یکتای ردیف | C2: - | D2: integer | E2: پایگاه داده فرآیند | F2: شناسه | G2: کلید اتصال با Process_Data و Dewatering_Balance
A3: DateTime | B3: تاریخ و زمان ثبت (هر ۲ ساعت، استاندارد ISO) | C3: - | D3: text | E3: اتوماسیون/SCADA | F3: زمان‌بندی | G3: مبنای تحلیل سری زمانی؛ مستقیماً در Power BI/Python قابل تبدیل است
A4: Shift | B4: شیفت کاری (A=00-08، B=08-16، C=16-24) | C4: - | D4: text | E4: گزارش شیفت | F4: دسته‌بندی | G4: مقایسه عملکرد بین شیفت‌ها
A5: Ore_Blend | B5: نوع خوراک ورودی کارخانه | C5: - | D5: text | E5: انباشت و برداشت | F5: علت‌یابی | G5: تغییر ترکیب خوراک روی عیار و بازیابی اثر دارد
A6: Circuit_Mode | B6: آرایش مدار جدایش (LIMS / LIMS_WHIMS / LIMS_Flotation) | C6: - | D6: text | E6: پانل کنترل مرکزی | F6: شرایط مدار | G6: تغییر رژیم فرآیندی؛ تعیین‌کننده ستون‌های فعال داده
A7: Feed_Wet_tph | B7: دبی جرمی تر خوراک ورودی | C7: t/h | D7: number | E7: توزین‌کننده نوار خوراک | F7: متغیر فرآیند | G7: افزایش بار هیدرولیکی تیکنر و فیلتر را در پی دارد
A8: Feed_Solids_pct | B8: درصد جامد پالپ خوراک ورودی | C8: % | D8: number | E8: دانسیته‌سنج خط خوراک | F8: علت‌یابی | G8: درصد جامد بالا → حمل مکانیکی گانگ در LIMS و افت عیار کنسانتره
A9: Feed_Moisture_pct | B9: درصد رطوبت خوراک (100 منهای Feed_Solids_pct) | C9: % | D9: number | E9: محاسبه‌شده | F9: متغیر فرآیند | G9: مبنای تبدیل جریان تر به خشک
A10: Feed_Fe_pct | B10: عیار آهن کل خوراک ورودی | C10: % | D10: number | E10: آنالایزر برخط / آزمایشگاه | F10: کیفیت خوراک | G10: مخرج محاسبه Fe_Recovery و Fe_Balance_Error
A11: Feed_SiO2_pct | B11: عیار سیلیس خوراک ورودی | C11: % | D11: number | E11: آزمایشگاه XRF | F11: کیفیت خوراک | G11: سیلیس بالا نیازمند معرف و میدان بیشتر است
A12: Feed_P80_um | B12: اندازه ۸۰٪ عبوری ذرات خوراک | C12: µm | D12: number | E12: PSI / آزمایشگاه دانه‌بندی | F12: علت‌یابی | G12: خارج از پنجره بهینه روی آزادی و اسلایم اثر می‌گذارد
... A52: Quality_Flag | B52: برچسب وضعیت کیفی دوره | C52: - | D52: text | E52: سیستم QC آموزشی | F52: برچسب | G52: OK / Slimes_High / Matrix_Blinding / Flocculant_Disturbance / Vacuum_Loss / Water_Quality / Balance_Check — برای آموزش عیب‌یابی بدون ستون Root_Cause

Sheet Process_Data
B1: Record_ID | C1: DateTime | D1: Shift | E1: Ore_Blend | F1: Circuit_Mode | G1: Feed_Wet_tph | H1: Feed_Solids_pct | I1: Feed_Moisture_pct | J1: Feed_Fe_pct | K1: Feed_SiO2_pct | L1: Feed_P80_um | M1: Feed_Slimes_pct | N1: Liberation_pct | O1: LIMS_Field_mT | P1: LIMS_Drum_Speed_rpm | Q1: LIMS_Splitter_pct | R1: WHIMS_Field_T | S1: Matrix_Condition_pct | T1: Matrix_Wash_Interval_h | U1: Flotation_pH | V1: Amine_Dose_gpt | W1: Starch_Dose_gpt | X1: Froth_Height_cm | Y1: Air_Flow_Nm3_h | Z1: Process_Water_Hardness_mgL | AA1: Process_Water_Turbidity_NTU | AH1: Feed_Dry_tph | AI1: Concentrate_Dry_tph | AJ1: Tailings_Dry_tph | AK1: Concentrate_Fe_pct | AL1: Concentrate_SiO2_pct | AM1: Tailings_Fe_pct | AN1: Tailings_SiO2_pct | AO1: دبی خشک خوراک | AP1: بازده جرمی کنسانتره | AQ1: بازیابی آهن | AR1: خطای موازنه آهن | AS1: انحراف موزانه آهن
B2: 1 | C2: 2026-09-01 00:00 | D2: A | E2: Blend_A | F2: LIMS | G2: 629 | H2: 32.8 | I2: 67.2 | J2: 37.76 | K2: 44.65 | L2: 104.3 | M2: 13 | N2: 83 | O2: 143 | P2: 22.1 | Q2: 49.4 | Z2: 152 | AA2: 29.9 | AH2: 206.312 | AI2: 96.1 | AJ2: 109.4 | AK2: 66.29 | AL2: 5.52 | AM2: 12.73 | AN2: 60.62 | AO2: =G2*(H2/100) -> 206.312 | AP2: =(AI2/AH2)*100 -> 46.579937 | AQ2: =(AI2*AK2)/(AH2*J2)*100 -> 81.773942 | AR2: =((AH2*J2)-(AI2*AK2+AJ2*AM2))/(AH2*J2)*100 -> 0.34928021 | AS2: =ABS(AR2)>5 -> FALSE
B3: 2 | C3: 2026-09-01 02:00 | D3: A | E3: Blend_A | F3: LIMS | G3: 592.3 | H3: 33.7 | I3: 66.3 | J3: 38.59 | K3: 43.84 | L3: 92.1 | M3: 10.4 | N3: 85.4 | O3: 145 | P3: 22.8 | Q3: 45.7 | Z3: 239 | AA3: 38.2 | AH3: 199.6051 | AI3: 102.7 | AJ3: 97.5 | AK3: 65.16 | AL3: 4.61 | AM3: 10.59 | AN3: 62.28 | AO3: =G3*(H3/100) -> 199.6051 | AP3: =(AI3/AH3)*100 -> 51.451591 | AQ3: =(AI3*AK3)/(AH3*J3)*100 -> 86.877058 | AR3: =((AH3*J3)-(AI3*AK3+AJ3*AM3))/(AH3*J3)*100 -> -0.28166772 | AS3: =ABS(AR3)>5 -> FALSE
B4: 3 | C4: 2026-09-01 04:00 | D4: A | E4: Blend_A | F4: LIMS | G4: 665.3 | H4: 34.1 | I4: 65.9 | J4: 37.98 | K4: 44.95 | L4: 100.2 | M4: 11.8 | N4: 87.7 | O4: 157 | P4: 21.1 | Q4: 49.3 | Z4: 143 | AA4: 18.2 | AH4: 226.8673 | AI4: 111.3 | AJ4: 116.4 | AK4: 64.82 | AL4: 6.08 | AM4: 12.33 | AN4: 64.43 | AO4: =G4*(H4/100) -> 226.8673 | AP4: =(AI4/AH4)*100 -> 49.059516 | AQ4: =(AI4*AK4)/(AH4*J4)*100 -> 83.729275 | AR4: =((AH4*J4)-(AI4*AK4+AJ4*AM4))/(AH4*J4)*100 -> -0.38598334 | AS4: =ABS(AR4)>5 -> FALSE
B5: 4 | C5: 2026-09-01 06:00 | D5: A | E5: Blend_A | F5: LIMS | G5: 574.3 | H5: 36 | I5: 64 | J5: 39.66 | K5: 42.44 | L5: 102.9 | M5: 10.6 | N5: 81.1 | O5: 148 | P5: 20.6 | Q5: 53.2 | Z5: 226 | AA5: 15.2 | AH5: 206.748 | AI5: 106.3 | AJ5: 100 | AK5: 66.42 | AL5: 4.93 | AM5: 11.24 | AN5: 62.11 | AO5: =G5*(H5/100) -> 206.748 | AP5: =(AI5/AH5)*100 -> 51.415249 | AQ5: =(AI5*AK5)/(AH5*J5)*100 -> 86.106931 | AR5: =((AH5*J5)-(AI5*AK5+AJ5*AM5))/(AH5*J5)*100 -> 0.1851265 | AS5: =ABS(AR5)>5 -> FALSE
B6: 5 | C6: 2026-09-01 08:00 | D6: B | E6: Blend_A | F6: LIMS | G6: 629.2 | H6: 34.3 | I6: 65.7 | J6: 37.71 | K6: 46.4 | L6: 103.2 | M6: 10.2 | N6: 81.4 | O6: 157 | P6: 23.9 | Q6: 47.4 | Z6: 207 | AA6: 37.8 | AH6: 215.8156 | AI6: 107.9 | AJ6: 107.6 | AK6: 65.68 | AL6: 5.65 | AM6: 9.56 | AN6: 63.58 | AO6: =G6*(H6/100) -> 215.8156 | AP6: =(AI6/AH6)*100 -> 49.996386 | AQ6: =(AI6*AK6)/(AH6*J6)*100 -> 87.079359 | AR6: =((AH6*J6)-(AI6*AK6+AJ6*AM6))/(AH6*J6)*100 -> 0.28111494 | AS6: =ABS(AR6)>5 -> FALSE
B7: 6 | C7: 2026-09-01 10:00 | D7: B | E7: Blend_A | F7: LIMS | G7: 572.7 | H7: 35.1 | I7: 64.9 | J7: 39.05 | K7: 42.94 | L7: 87.8 | M7: 10.7 | N7: 81.1 | O7: 172 | P7: 23.3 | Q7: 47.6 | Z7: 206 | AA7: 39.5 | AH7: 201.0177 | AI7: 100.4 | AJ7: 100.7 | AK7: 66.27 | AL7: 5.83 | AM7: 11.75 | AN7: 60.59 | AO7: =G7*(H7/100) -> 201.0177 | AP7: =(AI7/AH7)*100 -> 49.945851 | AQ7: =(AI7*AK7)/(AH7*J7)*100 -> 84.760858 | AR7: =((AH7*J7)-(AI7*AK7+AJ7*AM7))/(AH7*J7)*100 -> 0.16571483 | AS7: =ABS(AR7)>5 -> FALSE
B8: 7 | C8: 2026-09-01 12:00 | D8: B | E8: Blend_A | F8: LIMS | G8: 628.8 | H8: 32 | I8: 68 | J8: 37.91 | K8: 45.17 | L8: 85.1 | M8: 9.8 | N8: 85.5 | O8: 164 | P8: 21.9 | Q8: 47.2 | Z8: 211 | AA8: 22.1 | AH8: 201.216 | AI8: 98.5 | AJ8: 103 | AK8: 65.29 | AL8: 6.02 | AM8: 11.71 | AN8: 65.56 | AO8: =G8*(H8/100) -> 201.216 | AP8: =(AI8/AH8)*100 -> 48.95237 | AQ8: =(AI8*AK8)/(AH8*J8)*100 -> 84.307576 | AR8: =((AH8*J8)-(AI8*AK8+AJ8*AM8))/(AH8*J8)*100 -> -0.11924911 | AS8: =ABS(AR8)>5 -> FALSE
B9: 8 | C9: 2026-09-01 14:00 | D9: B | E9: Blend_A | F9: LIMS | G9: 614 | H9: 32.9 | I9: 67.1 | J9: 40.39 | K9: 42.77 | L9: 85.5 | M9: 12.2 | N9: 81.8 | O9: 173 | P9: 23.7 | Q9: 54.1 | Z9: 177 | AA9: 15.5 | AH9: 202.006 | AI9: 106.4 | AJ9: 96 | AK9: 66.37 | AL9: 5.68 | AM9: 11.5 | AN9: 60.68 | AO9: =G9*(H9/100) -> 202.006 | AP9: =(AI9/AH9)*100 -> 52.671703 | AQ9: =(AI9*AK9)/(AH9*J9)*100 -> 86.551644 | AR9: =((AH9*J9)-(AI9*AK9+AJ9*AM9))/(AH9*J9)*100 -> -0.082677308 | AS9: =ABS(AR9)>5 -> FALSE
B10: 9 | C10: 2026-09-01 16:00 | D10: C | E10: Blend_A | F10: LIMS | G10: 568.2 | H10: 34.3 | I10: 65.7 | J10: 41.01 | K10: 40.79 | L10: 98.9 | M10: 12.5 | N10: 83.6 | O10: 150 | P10: 22.9 | Q10: 53.1 | Z10: 227 | AA10: 42.4 | AH10: 194.8926 | AI10: 108.7 | AJ10: 86.1 | AK10: 64.57 | AL10: 5.29 | AM10: 11.4 | AN10: 62.01 | AO10: =G10*(H10/100) -> 194.8926 | AP10: =(AI10/AH10)*100 -> 55.774309 | AQ10: =(AI10*AK10)/(AH10*J10)*100 -> 87.816316 | AR10: =((AH10*J10)-(AI10*AK10+AJ10*AM10))/(AH10*J10)*100 -> -0.097008819 | AS10: =ABS(AR10)>5 -> FALSE
B11: 10 | C11: 2026-09-01 18:00 | D11: C | E11: Blend_A | F11: LIMS | G11: 554.9 | H11: 35.7 | I11: 64.3 | J11: 38.94 | K11: 45.11 | L11: 95.4 | M11: 12.8 | N11: 82.2 | O11: 162 | P11: 18.5 | Q11: 45.5 | Z11: 193 | AA11: 31.2 | AH11: 198.0993 | AI11: 100.2 | AJ11: 97.5 | AK11: 66.17 | AL11: 5.68 | AM11: 10.93 | AN11: 61.21 | AO11: =G11*(H11/100) -> 198.0993 | AP11: =(AI11/AH11)*100 -> 50.580694 | AQ11: =(AI11*AK11)/(AH11*J11)*100 -> 85.950809 | AR11: =((AH11*J11)-(AI11*AK11+AJ11*AM11))/(AH11*J11)*100 -> 0.23435018 | AS11: =ABS(AR11)>5 -> FALSE
B12: 11 | C12: 2026-09-01 20:00 | D12: C | E12: Blend_A | F12: LIMS | G12: 621.4 | H12: 35.2 | I12: 64.8 | J12: 40.14 | K12: 43.11 | L12: 104.1 | M12: 12.7 | N12: 85.5 | O12: 161 | P12: 20.5 | Q12: 47.5 | Z12: 176 | AA12: 37.7 | AH12: 218.7328 | AI12: 115.6 | AJ12: 102.7 | AK12: 65.37 | AL12: 5.18 | AM12: 11.66 | AN12: 64.45 | AO12: =G12*(H12/100) -> 218.7328 | AP12: =(AI12/AH12)*100 -> 52.84987 | AQ12: =(AI12*AK12)/(AH12*J12)*100 -> 86.068659 | AR12: =((AH12*J12)-(AI12*AK12+AJ12*AM12))/(AH12*J12)*100 -> 0.29249184 | AS12: =ABS(AR12)>5 -> FALSE
B13: 12 | C13: 2026-09-01 22:00 | D13: C | E13: Blend_A | F13: LIMS | G13: 631.4 | H13: 34.3 | I13: 65.7 | J13: 40.93 | K13: 41.1 | L13: 88.3 | M13: 9.4 | N13: 86.4 | O13: 141 | P13: 21.5 | Q13: 54.4 | Z13: 198 | AA13: 26.6 | AH13: 216.5702 | AI13: 123.1 | AJ13: 93.2 | AK13: 64.69 | AL13: 5.66 | AM13: 9.75 | AN13: 62.23 | AO13: =G13*(H13/100) -> 216.5702 | AP13: =(AI13/AH13)*100 -> 56.840692 | AQ13: =(AI13*AK13)/(AH13*J13)*100 -> 89.836901 | AR13: =((AH13*J13)-(AI13*AK13+AJ13*AM13))/(AH13*J13)*100 -> -0.088227904 | AS13: =ABS(AR13)>5 -> FALSE
... B74: 73 | C74: 2026-09-07 00:00 | D74: A | E74: Blend_A | F74: LIMS | G74: 642.3 | H74: 33.4 | I74: 66.6 | J74: 39.38 | K74: 42.78 | L74: 94.2 | M74: 18.3 | N74: 73 | O74: 169 | P74: 20 | Q74: 46.7 | Z74: 211 | AA74: 39.8 | AH74: 214.5282 | AI74: 105 | AJ74: 109.6 | AK74: 64.16 | AL74: 7.77 | AM74: 15.57 | AN74: 60.06 | AO74: =G74*(H74/100) -> 214.5282 | AP74: =(AI74/AH74)*100 -> 48.944614 | AQ74: =(AI74*AK74)/(AH74*J74)*100 -> 79.743181 | AR74: =((AH74*J74)-(AI74*AK74+AJ74*AM74))/(AH74*J74)*100 -> 0.057391653 | AS74: =ABS(AR74)>5 -> FALSE
B75: 74 | C75: 2026-09-07 02:00 | D75: A | E75: Blend_A | F75: LIMS | G75: 559.1 | H75: 32.8 | I75: 67.2 | J75: 40.92 | K75: 42.19 | L75: 101.7 | M75: 17.9 | N75: 73.9 | O75: 164 | P75: 21.1 | Q75: 48.1 | Z75: 161 | AA75: 16
B76: 75 | C76: 2026-09-07 04:00 | D76: A | E76: Blend_A | F76: LIMS | G76: 677 | H76: 32.5 | I76: 67.5 | J76: 39.19 | K76: 44.99 | L76: 99.8 | M76: 21.1 | N76: 71.7 | O76: 170 | P76: 19.8 | Q76: 54.1 | Z76: 215 | AA76: 39.1
B77: 76 | C77: 2026-09-07 06:00 | D77: A | E77: Blend_A | F77: LIMS | G77: 589 | H77: 35.3 | I77: 64.7 | J77: 37.69 | K77: 44.86 | L77: 102 | M77: 19.8 | N77: 73.6 | O77: 171 | P77: 19.1 | Q77: 45.8 | Z77: 164 | AA77: 38.8
B78: 77 | C78: 2026-09-07 08:00 | D78: B | E78: Blend_A | F78: LIMS | G78: 591.2 | H78: 34 | I78: 66 | J78: 40.6 | K78: 41.69 | L78: 102.9 | M78: 18.7 | N78: 73.6 | O78: 162 | P78: 21.6 | Q78: 52 | Z78: 164 | AA78: 30.4
B79: 78 | C79: 2026-09-07 10:00 | D79: B | E79: Blend_A | F79: LIMS | G79: 593.1 | H79: 34.2 | I79: 65.8 | J79: 38.28 | K79: 44.79 | L79: 90.6 | M79: 17.5 | N79: 73.1 | O79: 140 | P79: 18 | Q79: 47.2 | Z79: 144 | AA79: 18.2
B80: 79 | C80: 2026-09-07 12:00 | D80: B | E80: Blend_A | F80: LIMS | G80: 585.7 | H80: 33.8 | I80: 66.2 | J80: 39.19 | K80: 44.07 | L80: 103.2 | M80: 20.1 | N80: 73.6 | O80: 151 | P80: 22.9 | Q80: 54.6 | Z80: 222 | AA80: 15
B81: 80 | C81: 2026-09-07 14:00 | D81: B | E81: Blend_A | F81: LIMS | G81: 636.9 | H81: 35.1 | I81: 64.9 | J81: 38.95 | K81: 43.94 | L81: 85.2 | M81: 19.7 | N81: 75.5 | O81: 161 | P81: 23.2 | Q81: 52.2 | Z81: 152 | AA81: 42.1
B82: 81 | C82: 2026-09-07 16:00 | D82: C | E82: Blend_A | F82: LIMS | G82: 637.5 | H82: 33.2 | I82: 66.8 | J82: 38.73 | K82: 43.75 | L82: 93.9 | M82: 20.5 | N82: 74.9 | W82: 172 | X82: 32.5
B83: 82 | C83: 2026-09-07 18:00 | D83: C | E83: Blend_A | F83: LIMS | G83: 590.5 | H83: 35 | I83: 65 | J83: 39.92 | K83: 43.19 | L83: 89.4 | M83: 21.4 | N83: 72.7 | O83: 164 | P83: 18.8 | Q83: 49.9 | Z83: 143 | AA83: 30.2
B84: 83 | C84: 2026-09-07 20:00 | D84: C | E84: Blend_A | F84: LIMS | G84: 677.9 | H84: 33.3 | I84: 66.7 | J84: 41.34 | K84: 41.21 | L84: 92.7 | M84: 18.2 | N84: 73.2 | O84: 145 | P84: 21.3 | Q84: 50.4 | Z84: 216 | AA84: 40
B85: 84 | C85: 2026-09-07 22:00 | D85: C | E85: Blend_A | F85: LIMS | G85: 664.4 | H85: 34.8 | I85: 65.2 | J85: 39.78 | K85: 42.75 | L85: 89 | M85: 18.5 | N85: 70.2 | O85: 157 | P85: 21.3 | Q85: 47.3 | Z85: 236 | AA85: 42.3
B86: 85 | C86: 2026-09-08 00:00 | D86: A | E86: Blend_B | F86: LIMS | G86: 587.2 | H86: 32.9 | I86: 67.1 | J86: 41.43 | K86: 40.79 | L86: 94.8 | M86: 11.9 | N86: 88.7 | O86: 174 | P86: 20.4 | Q86: 53.3 | Z86: 216 | AA86: 32.2
B87: 86 | C87: 2026-09-08 02:00 | D87: A | E87: Blend_B | F87: LIMS | G87: 640 | H87: 32.6 | I87: 67.4 | J87: 39.56 | K87: 42.59 | L87: 90.6 | M87: 10.1 | N87: 89.6 | O87: 140 | P87: 24 | Q87: 51.8 | Z87: 223 | AA87: 23.8
B88: 87 | C88: 2026-09-08 04:00 | D88: A | E88: Blend_B | F88: LIMS | G88: 595.3 | H88: 32.5 | I88: 67.5 | J88: 42.18 | K88: 40.88 | L88: 104.1 | M88: 11.6 | N88: 83 | O88: 143 | P88: 21 | Q88: 52.9 | Z88: 211 | AA88: 16.5
B89: 88 | C89: 2026-09-08 06:00 | D89: A | E89: Blend_B | F89: LIMS | G89: 566 | H89: 36 | I89: 64 | J89: 40.46 | K89: 41.91 | L89: 97.5 | M89: 9.4 | N89: 86.8 | O89: 148 | P89: 22.3 | Q89: 53.2 | Z89: 220 | AA89: 31.6
B90: 89 | C90: 2026-09-08 08:00 | D90: B | E90: Blend_B | F90: LIMS | G90: 659.1 | H90: 32 | I90: 68 | J90: 39.73 | K90: 43.58 | L90: 87 | M90: 10.8 | N90: 82.7 | O90: 169 | P90: 19.9 | Q90: 52.9 | Z90: 229 | AA90: 28
B91: 90 | C91: 2026-09-08 10:00 | D91: B | E91: Blend_B | F91: LIMS | G91: 588.7 | H91: 32.5 | I91: 67.5 | J91: 41.77 | K91: 41.49 | L91: 92.2 | M91: 13.8 | N91: 85 | O91: 155 | P91: 20.7 | Q91: 47.1 | Z91: 177 | AA91: 26.1
B92: 91 | C92: 2026-09-08 12:00 | D92: B | E92: Blend_B | F92: LIMS | G92: 633.8 | H92: 33.8 | I92: 66.2 | J92: 41.05 | K92: 40.35 | L92: 90.7 | M92: 10.8 | N92: 80.6 | O92: 144 | P92: 21.1 | Q92: 47.7 | Z92: 224 | AA92: 15.4
B93: 92 | C93: 2026-09-08 14:00 | D93: B | E93: Blend_B | F93: LIMS | G93: 617.8 | H93: 36.4 | I93: 63.6 | J93: 38.52 | K93: 44.07 | L93: 101.1 | M93: 9.6 | N93: 82.7 | O93: 141 | P93: 19.8 | Q93: 52.7 | Z93: 192 | AA93: 25.4
B94: 93 | C94: 2026-09-08 16:00 | D94: C | E94: Blend_B | F94: LIMS | G94: 647.2 | H94: 34.1 | I94: 65.9 | J94: 39.19 | K94: 42.74 | L94: 100.7 | M94: 14 | N94: 85.4 | O94: 174 | P94: 18.5 | Q94: 48.7 | Z94: 163 | AA94: 20.9
... B109: 108 | C109: 2026-09-09 22:00 | D109: C | E109: Blend_A | F109: LIMS | G109: 603.3 | H109: 34.9 | I109: 65.1 | J109: 38.54 | K109: 45.57 | L109: 88.2 | M109: 9.4 | N109: 81.9 | O109: 163 | P109: 23.3 | Q109: 53.1 | Z109: 209 | AA109: 18.3

Sheet Dewatering_Balance
A1: Record_ID | B1: Thickener_Flocculant_Dose_gpt | C1: Thickener_Overflow_Turbidity_NTU | D1: Thickener_Underflow_Solids_pct | E1: Thickener_Bed_Level_pct | F1: Thickener_Rake_Torque_pct | G1: Filter_Vacuum_kPa | H1: Filter_Cycle_Time_min | I1: Filter_Cloth_Condition_pct | J1: Filter_Feed_Solids_pct | K1: Filter_Cake_Moisture_pct | L1: Filterate_Turbidity_NTU | M1: Feed_Dry_tph | N1: Concentrate_Dry_tph | O1: Tailings_Dry_tph | P1: Concentrate_Fe_pct | Q1: Concentrate_SiO2_pct | R1: Tailings_Fe_pct | S1: Tailings_SiO2_pct | T1: Mass_Yield_pct | U1: Fe_Recovery_pct | V1: Tailings_Fe_Recovery_pct | W1: Rec_Check_pct | X1: Mass_Balance_Error_pct | Y1: Fe_Balance_Error_pct | Z1: Quality_Flag
A2: 1 | B2: 20.3 | C2: 142.7 | D2: 59.6 | E2: 44.9 | F2: 21.1 | G2: 74.7 | H2: 5.6 | I2: 95.8 | J2: 58.4 | K2: 10.2 | L2: 91.7 | M2: =Process_Data!G2*Process_Data!H2/100 -> 206.312 | N2: 96.1 | O2: 109.4 | P2: 66.29 | Q2: 5.52 | R2: 12.73 | S2: 60.62 | T2: =N2/M2*100 -> 46.579937 | U2: =N2*P2/(M2*Process_Data!J2)*100 -> 81.773942 | V2: =O2*R2/(M2*Process_Data!J2)*100 -> 17.876778 | W2: =U2+V2 -> 99.65072 | X2: =(M2-(N2+O2))/M2*100 -> 0.39357866 | Y2: =(M2*Process_Data!J2-(N2*P2+O2*R2))/(M2*Process_Data!J2)*100 -> 0.34928021 | Z2: OK
A3: 2 | B3: 21.6 | C3: 70.4 | D3: 62.9 | E3: 45.6 | F3: 25.3 | G3: 76.2 | H3: 4.6 | I3: 89.8 | J3: 61.4 | K3: 10.4 | L3: 74.3 | M3: =Process_Data!G3*Process_Data!H3/100 -> 199.6051 | N3: 102.7 | O3: 97.5 | P3: 65.16 | Q3: 4.61 | R3: 10.59 | S3: 62.28 | T3: =N3/M3*100 -> 51.451591 | U3: =N3*P3/(M3*Process_Data!J3)*100 -> 86.877058 | V3: =O3*R3/(M3*Process_Data!J3)*100 -> 13.404609 | W3: =U3+V3 -> 100.28167 | X3: =(M3-(N3+O3))/M3*100 -> -0.29803848 | Y3: =(M3*Process_Data!J3-(N3*P3+O3*R3))/(M3*Process_Data!J3)*100 -> -0.28166772 | Z3: OK
A4: 3 | B4: 20.3 | C4: 120.9 | D4: 59.9 | E4: 42.6 | F4: 27.1 | G4: 79.8 | H4: 5.3 | I4: 90.6 | J4: 59.1 | K4: 8.9 | L4: 55.9 | M4: =Process_Data!G4*Process_Data!H4/100 -> 226.8673 | N4: 111.3 | O4: 116.4 | P4: 64.82 | Q4: 6.08 | R4: 12.33 | S4: 64.43 | T4: =N4/M4*100 -> 49.059516 | U4: =N4*P4/(M4*Process_Data!J4)*100 -> 83.729275 | V4: =O4*R4/(M4*Process_Data!J4)*100 -> 16.656709 | W4: =U4+V4 -> 100.38598 | X4: =(M4-(N4+O4))/M4*100 -> -0.36704276 | Y4: =(M4*Process_Data!J4-(N4*P4+O4*R4))/(M4*Process_Data!J4)*100 -> -0.38598334 | Z4: OK
A5: 4 | B5: 24.1 | C5: 103.4 | D5: 59.3 | E5: 36.8 | F5: 21.4 | G5: 77.7 | H5: 5.1 | I5: 93.9 | J5: 57.6 | K5: 9.5 | L5: 93.4 | M5: =Process_Data!G5*Process_Data!H5/100 -> 206.748 | N5: 106.3 | O5: 100 | P5: 66.42 | Q5: 4.93 | R5: 11.24 | S5: 62.11 | T5: =N5/M5*100 -> 51.415249 | U5: =N5*P5/(M5*Process_Data!J5)*100 -> 86.106931 | V5: =O5*R5/(M5*Process_Data!J5)*100 -> 13.707943 | W5: =U5+V5 -> 99.814874 | X5: =(M5-(N5+O5))/M5*100 -> 0.21668892 | Y5: =(M5*Process_Data!J5-(N5*P5+O5*R5))/(M5*Process_Data!J5)*100 -> 0.1851265 | Z5: OK
A6: 5 | B6: 21.9 | C6: 128.3 | D6: 60.2 | E6: 44.5 | F6: 24.3 | G6: 80.5 | H6: 4.7 | I6: 91.2 | J6: 59 | K6: 9.1 | L6: 42.2 | M6: =Process_Data!G6*Process_Data!H6/100 -> 215.8156 | N6: 107.9 | O6: 107.6 | P6: 65.68 | Q6: 5.65 | R6: 9.56 | S6: 63.58 | T6: =N6/M6*100 -> 49.996386 | U6: =N6*P6/(M6*Process_Data!J6)*100 -> 87.079359 | V6: =O6*R6/(M6*Process_Data!J6)*100 -> 12.639526 | W6: =U6+V6 -> 99.718885 | X6: =(M6-(N6+O6))/M6*100 -> 0.14623595 | Y6: =(M6*Process_Data!J6-(N6*P6+O6*R6))/(M6*Process_Data!J6)*100 -> 0.28111494 | Z6: OK
A7: 6 | B7: 24.4 | C7: 112.4 | D7: 59.5 | E7: 36.4 | F7: 27 | G7: 76.1 | H7: 5.8 | I7: 91.4 | J7: 57.8 | K7: 10.1 | L7: 89.3 | M7: =Process_Data!G7*Process_Data!H7/100 -> 201.0177 | N7: 100.4 | O7: 100.7 | P7: 66.27 | Q7: 5.83 | R7: 11.75 | S7: 60.59 | T7: =N7/M7*100 -> 49.945851 | U7: =N7*P7/(M7*Process_Data!J7)*100 -> 84.760858 | V7: =O7*R7/(M7*Process_Data!J7)*100 -> 15.073427 | W7: =U7+V7 -> 99.834285 | X7: =(M7-(N7+O7))/M7*100 -> -0.040941668 | Y7: =(M7*Process_Data!J7-(N7*P7+O7*R7))/(M7*Process_Data!J7)*100 -> 0.16571483 | Z7: OK
A8: 7 | B8: 22.6 | C8: 129.7 | D8: 61.9 | E8: 47.7 | F8: 24.6 | G8: 76.3 | H8: 4.7 | I8: 90.9 | J8: 60.7 | K8: 9.2 | L8: 93.5 | M8: =Process_Data!G8*Process_Data!H8/100 -> 201.216 | N8: 98.5 | O8: 103 | P8: 65.29 | Q8: 6.02 | R8: 11.71 | S8: 65.56 | T8: =N8/M8*100 -> 48.95237 | U8: =N8*P8/(M8*Process_Data!J8)*100 -> 84.307576 | V8: =O8*R8/(M8*Process_Data!J8)*100 -> 15.811673 | W8: =U8+V8 -> 100.11925 | X8: =(M8-(N8+O8))/M8*100 -> -0.14114186 | Y8: =(M8*Process_Data!J8-(N8*P8+O8*R8))/(M8*Process_Data!J8)*100 -> -0.11924911 | Z8: OK
A9: 8 | B9: 27.4 | C9: 104.3 | D9: 63.8 | E9: 49.5 | F9: 26.5 | G9: 80.7 | H9: 5.3 | I9: 91.2 | J9: 62.9 | K9: 9.1 | L9: 70.6 | M9: =Process_Data!G9*Process_Data!H9/100 -> 202.006 | N9: 106.4 | O9: 96 | P9: 66.37 | Q9: 5.68 | R9: 11.5 | S9: 60.68 | T9: =N9/M9*100 -> 52.671703 | U9: =N9*P9/(M9*Process_Data!J9)*100 -> 86.551644 | V9: =O9*R9/(M9*Process_Data!J9)*100 -> 13.531033 | W9: =U9+V9 -> 100.08268 | X9: =(M9-(N9+O9))/M9*100 -> -0.19504371 | Y9: =(M9*Process_Data!J9-(N9*P9+O9*R9))/(M9*Process_Data!J9)*100 -> -0.082677308 | Z9: OK
A10: 9 | B10: 24.1 | C10: 110.1 | D10: 62.8 | E10: 44.7 | F10: 25 | G10: 76 | H10: 6.3 | I10: 91.6 | J10: 61.3 | K10: 9 | L10: 71.8 | M10: =Process_Data!G10*Process_Data!H10/100 -> 194.8926 | N10: 108.7 | O10: 86.1 | P10: 64.57 | Q10: 5.29 | R10: 11.4 | S10: 62.01 | T10: =N10/M10*100 -> 55.774309 | U10: =N10*P10/(M10*Process_Data!J10)*100 -> 87.816316 | V10: =O10*R10/(M10*Process_Data!J10)*100 -> 12.280693 | W10: =U10+V10 -> 100.09701 | X10: =(M10-(N10+O10))/M10*100 -> 0.047513348 | Y10: =(M10*Process_Data!J10-(N10*P10+O10*R10))/(M10*Process_Data!J10)*100 -> -0.097008819 | Z10: OK
A11: 10 | B11: 25.1 | C11: 128.1 | D11: 63.9 | E11: 42.7 | F11: 21.2 | G11: 77 | H11: 5 | I11: 89.5 | J11: 62.3 | K11: 8.8 | L11: 92.9 | M11: =Process_Data!G11*Process_Data!H11/100 -> 198.0993 | N11: 100.2 | O11: 97.5 | P11: 66.17 | Q11: 5.68 | R11: 10.93 | S11: 61.21 | T11: =N11/M11*100 -> 50.580694 | U11: =N11*P11/(M11*Process_Data!J11)*100 -> 85.950809 | V11: =O11*R11/(M11*Process_Data!J11)*100 -> 13.814841 | W11: =U11+V11 -> 99.76565 | X11: =(M11-(N11+O11))/M11*100 -> 0.20156558 | Y11: =(M11*Process_Data!J11-(N11*P11+O11*R11))/(M11*Process_Data!J11)*100 -> 0.23435018 | Z11: OK
A12: 11 | B12: 20.1 | C12: 79.3 | D12: 58.3 | E12: 35.6 | F12: 26.6 | G12: 73.9 | H12: 5.4 | I12: 92.4 | J12: 56.9 | K12: 9.7 | L12: 49.5 | M12: =Process_Data!G12*Process_Data!H12/100 -> 218.7328 | N12: 115.6 | O12: 102.7 | P12: 65.37 | Q12: 5.18 | R12: 11.66 | S12: 64.45 | T12: =N12/M12*100 -> 52.84987 | U12: =N12*P12/(M12*Process_Data!J12)*100 -> 86.068659 | V12: =O12*R12/(M12*Process_Data!J12)*100 -> 13.638849 | W12: =U12+V12 -> 99.707508 | X12: =(M12-(N12+O12))/M12*100 -> 0.19786699 | Y12: =(M12*Process_Data!J12-(N12*P12+O12*R12))/(M12*Process_Data!J12)*100 -> 0.29249184 | Z12: OK
A13: 12 | B13: 25.1 | C13: 106.7 | D13: 61.3 | E13: 49.1 | F13: 21.9 | G13: 74.8 | H13: 6.3 | I13: 89.5 | J13: 59.5 | K13: 9 | L13: 41 | M13: =Process_Data!G13*Process_Data!H13/100 -> 216.5702 | N13: 123.1 | O13: 93.2 | P13: 64.69 | Q13: 5.66 | R13: 9.75 | S13: 62.23 | T13: =N13/M13*100 -> 56.840692 | U13: =N13*P13/(M13*Process_Data!J13)*100 -> 89.836901 | V13: =O13*R13/(M13*Process_Data!J13)*100 -> 10.251327 | W13: =U13+V13 -> 100.08823 | X13: =(M13-(N13+O13))/M13*100 -> 0.12476324 | Y13: =(M13*Process_Data!J13-(N13*P13+O13*R13))/(M13*Process_Data!J13)*100 -> -0.088227904 | Z13: OK
... A74: 73 | B74: 25.7 | C74: 248.8 | D74: 52.6 | E74: 50.2 | F74: 32.5 | G74: 73 | H74: 5.8 | I74: 82.8 | J74: 51.1 | K74: 12.2 | L74: 118.3 | M74: =Process_Data!G74*Process_Data!H74/100 -> 214.5282 | N74: 105 | O74: 109.6 | P74: 64.16 | Q74: 7.77 | R74: 15.57 | S74: 60.06 | T74: =N74/M74*100 -> 48.944614 | U74: =N74*P74/(M74*Process_Data!J74)*100 -> 79.743181 | V74: =O74*R74/(M74*Process_Data!J74)*100 -> 20.199428 | W74: =U74+V74 -> 99.942608 | X74: =(M74-(N74+O74))/M74*100 -> -0.033468793 | Y74: =(M74*Process_Data!J74-(N74*P74+O74*R74))/(M74*Process_Data!J74)*100 -> 0.057391653 | Z74: Slimes_High

Sheet Calculations
A1: شاخص | B1: رابطه | C1: فرمول Excel | D1: توضیح فارسی
A2: بازده جرمی کنسانتره (Mass Yield) | B2: Y_c = (C / F_dry) × 100 | C2: Dewatering_Balance!N2/(Process_Data!F2*Process_Data!G2/100)*100 | D2: درصد جرمی خوراک خشک ورودی که به کنسانتره تبدیل شده است. مبنای توناژ خشک است.
A3: بازیابی آهن کنسانتره (Fe Recovery) | B3: R_Fe = (C × f_c) / (F_dry × f_f) × 100 | C3: (Dewatering_Balance!N2*Dewatering_Balance!P2)/((Process_Data!F2*Process_Data!G2/100)*Process_Data!I2)*100 | D3: درصد کل آهن موجود در خوراک که در محصول نهایی جذب شده است؛ شاخص اصلی متالورژیکی.
A4: بازیابی آهن باطله (Tailings Fe Recovery) | B4: R_Fe,t = (T × f_t) / (F_dry × f_f) × 100 | C4: (Dewatering_Balance!O2*Dewatering_Balance!R2)/((Process_Data!F2*Process_Data!G2/100)*Process_Data!I2)*100 | D4: درصد آهن تلف‌شده در جریان باطله؛ در شرایط نرمال باید حداقل نگه داشته شود.
A5: کنترل جمع بازیابی‌ها (Recovery Sum Check) | B5: Sum_Rec = R_Fe + R_Fe,t ≈ 100% | C5: U2+V2 | D5: کنترل منطقی سازگاری؛ انحراف معنادار از 100 نشانه خطای نمونه‌برداری، آنالیز یا اندازه‌گیری است.
A6: خطای موازنه جرمی (Mass Balance Error) | B6: Err_Mass = (F_dry - (C + T)) / F_dry × 100 | C6: ((Process_Data!F2*Process_Data!G2/100)-(Dewatering_Balance!N2+Dewatering_Balance!O2))/(Process_Data!F2*Process_Data!G2/100)*100 | D6: درصد اختلاف بین جریان خشک ورودی و مجموع خروجی‌ها؛ در شرایط پایدار معمولاً زیر ۱.۵٪ است.
A7: خطای موازنه آهن (Fe Balance Error) | B7: Err_Fe = (F_dry×f_f - (C×f_c + T×f_t)) / (F_dry×f_f) × 100 | C7: ((Process_Data!F2*Process_Data!G2/100)*Process_Data!I2-(Dewatering_Balance!N2*Dewatering_Balance!P2+Dewatering_Balance!O2*Dewatering_Balance!R2))/((Process_Data!F2*Process_Data!G2/100)*Process_Data!I2)*100 | D7: سازگاری عیارها و جریان‌ها؛ ابزار داده‌محور QC برای اعتبارسنجی ارقام پیش از تصمیم‌گیری فرآیندی.

Sheet SPC_Sample
A1: Record_ID | B1: DateTime | C1: Filter_Cake_Moisture_pct | D1: USL | E1: Target | F1: LSL | G1: Thickener_Overflow_Turbidity_NTU | H1: Tailings_Fe_pct
A2: 1 | B2: 2026-09-01 00:00 | C2: 10.2 | D2: 10.5 | E2: 9.5 | F2: 8.5 | G2: 142.7 | H2: 12.73
A3: 3 | B3: 2026-09-01 04:00 | C3: 8.9 | D3: 10.5 | E3: 9.5 | F3: 8.5 | G3: 120.9 | H3: 12.33
A4: 5 | B4: 2026-09-01 08:00 | C4: 9.1 | D4: 10.5 | E4: 9.5 | F4: 8.5 | G4: 128.3 | H4: 9.56
A5: 7 | B5: 2026-09-01 12:00 | C5: 9.2 | D5: 10.5 | E5: 9.5 | F5: 8.5 | G5: 129.7 | H5: 11.71
A6: 9 | B6: 2026-09-01 16:00 | C6: 9 | D6: 10.5 | E6: 9.5 | F6: 8.5 | G6: 110.1 | H6: 11.4
A7: 11 | B7: 2026-09-01 20:00 | C7: 9.7 | D7: 10.5 | E7: 9.5 | F7: 8.5 | G7: 79.3 | H7: 11.66
A8: 12 | B8: 2026-09-01 22:00 | C8: 9 | D8: 10.5 | E8: 9.5 | F8: 8.5 | G8: 106.7 | H8: 9.75
A9: 14 | B9: 2026-09-02 02:00 | C9: 9.1 | D9: 10.5 | E9: 9.5 | F9: 8.5 | G9: 77.3 | H9: 9.79
A10: 16 | B10: 2026-09-02 06:00 | C10: 9.6 | D10: 10.5 | E10: 9.5 | F10: 8.5 | G10: 106.4 | H10: 11.12
A11: 18 | B11: 2026-09-02 10:00 | C11: 9.7 | D11: 10.5 | E11: 9.5 | F11: 8.5 | G11: 88.3 | H11: 12.57
A12: 20 | B12: 2026-09-02 14:00 | C12: 8.9 | D12: 10.5 | E12: 9.5 | F12: 8.5 | G12: 84.2 | H12: 12.56
A13: 22 | B13: 2026-09-02 18:00 | C13: 9.1 | D13: 10.5 | E13: 9.5 | F13: 8.5 | G13: 118.5 | H13: 10.94
... A31: 56 | B31: 2026-09-05 14:00 | C31: 9.5 | D31: 10.5 | E31: 9.5 | F31: 8.5 | G31: 143.6 | H31: 12.27
A32: 57 | B32: 2026-09-05 14:01 | C32: 10.2 | D32: 10.5 | E32: 9.5 | F32: 8.5
A33: 58 | B33: 2026-09-05 14:02 | C33: 8.9 | D33: 10.5 | E33: 9.5 | F33: 8.5
A34: 59 | B34: 2026-09-05 14:03 | C34: 9.1 | D34: 10.5 | E34: 9.5 | F34: 8.5
A35: 60 | B35: 2026-09-05 14:04 | C35: 9.2 | D35: 10.5 | E35: 9.5 | F35: 8.5
A36: 61 | B36: 2026-09-05 14:05 | C36: 9 | D36: 10.5 | E36: 9.5 | F36: 8.5
A37: 62 | B37: 2026-09-05 14:06 | C37: 9.7 | D37: 10.5 | E37: 9.5 | F37: 8.5
A38: 63 | B38: 2026-09-05 14:07 | C38: 9 | D38: 10.5 | E38: 9.5 | F38: 8.5
A39: 64 | B39: 2026-09-05 14:08 | C39: 9.1 | D39: 10.5 | E39: 9.5 | F39: 8.5
A40: 65 | B40: 2026-09-05 14:09 | C40: 9.6 | D40: 10.5 | E40: 9.5 | F40: 8.5
A41: 66 | B41: 2026-09-05 14:10 | C41: 9.7 | D41: 10.5 | E41: 9.5 | F41: 8.5
A42: 67 | B42: 2026-09-05 14:11 | C42: 8.9 | D42: 10.5 | E42: 9.5 | F42: 8.5
A43: 68 | B43: 2026-09-05 14:12 | C43: 9.1 | D43: 10.5 | E43: 9.5 | F43: 8.5
... A74: 99 | B74: 2026-09-05 14:43 | C74: 9.1 | D74: 10.5 | E74: 9.5 | F74: 8.5

Sheet Dashboard_Data
A1: Date | B1: Shift | C1: Feed_Fe_avg | D1: Conc_Fe_avg | E1: Conc_SiO2_avg | F1: Fe_Rec_avg | G1: Cake_Moist_avg | H1: Ovf_Turb_avg | I1: Slimes_avg | J1: Flocc_avg | K1: MBErr_avg
A2: 45352 | B2: Shift_A | C2: 39.4 | D2: 67.8 | E2: 2.1 | F2: 86.4 | G2: 8.8 | H2: 18.5 | I2: 12.4 | J2: 14.2 | K2: 1.2
A3: 45352 | B3: Shift_B | C3: 40.1 | D3: 68.1 | E3: 1.9 | F3: 85.8 | G3: 8.6 | H3: 16.2 | I3: 11.8 | J3: 13.8 | K3: -0.8
A4: 45352 | B4: Shift_C | C4: 38.8 | D4: 67.4 | E4: 2.3 | F4: 87.1 | G4: 9.1 | H4: 24 | I4: 14.1 | J4: 15.5 | K4: 2.4
A5: 45353 | B5: Shift_A | C5: 39.7 | D5: 67.9 | E5: 2 | F5: 86.2 | G5: 8.7 | H5: 17.8 | I5: 12 | J5: 14 | K5: -1.5
A6: 45353 | B6: Shift_B | C6: 38.2 | D6: 67.2 | E6: 2.4 | F6: 86.9 | G6: 9.3 | H6: 28.5 | I6: 15.3 | J6: 16.2 | K6: 3.1
A7: 45353 | B7: Shift_C | C7: 40.5 | D7: 68.3 | E7: 1.8 | F7: 85.4 | G7: 8.5 | H7: 15.1 | I7: 11.2 | J7: 13.5 | K7: 0.4
A8: 45354 | B8: Shift_A | C8: 39 | D8: 67.6 | E8: 2.2 | F8: 86.7 | G8: 8.9 | H8: 19.4 | I8: 12.8 | J8: 14.5 | K8: -2.1
A9: 45354 | B9: Shift_B | C9: 37.9 | D9: 66.8 | E9: 2.7 | F9: 87.5 | G9: 9.6 | H9: 35.2 | I9: 16.4 | J9: 17.8 | K9: 5.4
A10: 45354 | B10: Shift_C | C10: 39.8 | D10: 68 | E10: 2 | F10: 86 | G10: 8.7 | H10: 18 | I10: 12.2 | J10: 14.1 | K10: 1.1
A11: 45355 | B11: Shift_A | C11: 40.2 | D11: 68.2 | E11: 1.9 | F11: 85.6 | G11: 8.6 | H11: 16.5 | I11: 11.5 | J11: 13.7 | K11: -0.6
A12: 45355 | B12: Shift_B | C12: 39.5 | D12: 67.7 | E12: 2.1 | F12: 86.3 | G12: 8.8 | H12: 20.1 | I12: 13 | J12: 14.6 | K12: 1.8
A13: 45355 | B13: Shift_C | C13: 38.6 | D13: 67.3 | E13: 2.3 | F13: 86.8 | G13: 9.2 | H13: 26.4 | I13: 14.7 | J13: 15.8 | K13: -1.9
... A16: 45356 | B16: Shift_C | C16: 40.6 | D16: 68.4 | E16: 1.7 | F16: 85.2 | G16: 8.4 | H16: 14.8 | I16: 10.9 | J16: 13.2 | K16: 0.2

Sheet Minitab_Import
A1: Feed_Wet_tph | B1: Feed_Solids_pct | C1: Feed_Moisture_pct | D1: Feed_Fe_pct | E1: Feed_SiO2_pct | F1: Feed_P80_um | G1: Feed_Slimes_pct | H1: Liberation_pct | I1: LIMS_Field_mT | J1: LIMS_Drum_Speed_rpm | K1: LIMS_Splitter_pct | L1: WHIMS_Field_T | M1: Matrix_Condition_pct | N1: Matrix_Wash_Interval_h | O1: Flotation_pH | P1: Amine_Dose_gpt | Q1: Starch_Dose_gpt | R1: Froth_Height_cm | S1: Air_Flow_Nm3_h | T1: Process_Water_Hardness_mgL | U1: Process_Water_Turbidity_NTU | V1: Filter_Cake_Moisture_pct
A2: 629 | B2: 32.8 | C2: 67.2 | D2: 37.76 | E2: 44.65 | F2: 104.3 | G2: 13 | H2: 83 | I2: 143 | J2: 22.1 | K2: 49.4 | T2: 152 | U2: 29.9 | V2: 10.2
A3: 592.3 | B3: 33.7 | C3: 66.3 | D3: 38.59 | E3: 43.84 | F3: 92.1 | G3: 10.4 | H3: 85.4 | I3: 145 | J3: 22.8 | K3: 45.7 | T3: 239 | U3: 38.2 | V3: 8.9
A4: 665.3 | B4: 34.1 | C4: 65.9 | D4: 37.98 | E4: 44.95 | F4: 100.2 | G4: 11.8 | H4: 87.7 | I4: 157 | J4: 21.1 | K4: 49.3 | T4: 143 | U4: 18.2 | V4: 9.1
A5: 574.3 | B5: 36 | C5: 64 | D5: 39.66 | E5: 42.44 | F5: 102.9 | G5: 10.6 | H5: 81.1 | I5: 148 | J5: 20.6 | K5: 53.2 | T5: 226 | U5: 15.2 | V5: 9.2
A6: 629.2 | B6: 34.3 | C6: 65.7 | D6: 37.71 | E6: 46.4 | F6: 103.2 | G6: 10.2 | H6: 81.4 | I6: 157 | J6: 23.9 | K6: 47.4 | T6: 207 | U6: 37.8 | V6: 9
A7: 572.7 | B7: 35.1 | C7: 64.9 | D7: 39.05 | E7: 42.94 | F7: 87.8 | G7: 10.7 | H7: 81.1 | I7: 172 | J7: 23.3 | K7: 47.6 | T7: 206 | U7: 39.5 | V7: 9.7
A8: 628.8 | B8: 32 | C8: 68 | D8: 37.91 | E8: 45.17 | F8: 85.1 | G8: 9.8 | H8: 85.5 | I8: 164 | J8: 21.9 | K8: 47.2 | T8: 211 | U8: 22.1 | V8: 9
A9: 614 | B9: 32.9 | C9: 67.1 | D9: 40.39 | E9: 42.77 | F9: 85.5 | G9: 12.2 | H9: 81.8 | I9: 173 | J9: 23.7 | K9: 54.1 | T9: 177 | U9: 15.5 | V9: 9.1
A10: 568.2 | B10: 34.3 | C10: 65.7 | D10: 41.01 | E10: 40.79 | F10: 98.9 | G10: 12.5 | H10: 83.6 | I10: 150 | J10: 22.9 | K10: 53.1 | T10: 227 | U10: 42.4 | V10: 9.6
A11: 554.9 | B11: 35.7 | C11: 64.3 | D11: 38.94 | E11: 45.11 | F11: 95.4 | G11: 12.8 | H11: 82.2 | I11: 162 | J11: 18.5 | K11: 45.5 | T11: 193 | U11: 31.2 | V11: 9.7
A12: 621.4 | B12: 35.2 | C12: 64.8 | D12: 40.14 | E12: 43.11 | F12: 104.1 | G12: 12.7 | H12: 85.5 | I12: 161 | J12: 20.5 | K12: 47.5 | T12: 176 | U12: 37.7 | V12: 8.9
A13: 631.4 | B13: 34.3 | C13: 65.7 | D13: 40.93 | E13: 41.1 | F13: 88.3 | G13: 9.4 | H13: 86.4 | I13: 141 | J13: 21.5 | K13: 54.4 | T13: 198 | U13: 26.6 | V13: 9.1
... A31: 562.9 | B31: 33.1 | C31: 66.9 | D31: 41.74 | E31: 39.57 | F31: 92.9 | G31: 12.3 | H31: 82 | I31: 150 | J31: 23.4 | K31: 45.1 | T31: 149 | U31: 21.2 | V31: 9.5
A32: 649.3 | B32: 32.6 | C32: 67.4 | D32: 41.96 | E32: 39.12 | F32: 101 | G32: 11.1 | H32: 80.2 | I32: 149 | J32: 21.2 | K32: 51.3 | T32: 166 | U32: 19.2
A33: 663.6 | B33: 34.7 | C33: 65.3 | D33: 41.07 | E33: 42.12 | F33: 103.3 | G33: 11.1 | H33: 83.8 | I33: 158 | J33: 18.3 | K33: 46.7 | T33: 214 | U33: 17.5
A34: 614.5 | B34: 34.7 | C34: 65.3 | D34: 40.11 | E34: 43.59 | F34: 86.5 | G34: 12.6 | H34: 85 | I34: 164 | J34: 20.6 | K34: 47.5 | T34: 222 | U34: 39
A35: 582.5 | B35: 34.2 | C35: 65.8 | D35: 39.87 | E35: 41.81 | F35: 85.8 | G35: 12.5 | H35: 89.3 | I35: 146 | J35: 21.4 | K35: 54.2 | T35: 143 | U35: 35.9
A36: 558.5 | B36: 33.4 | C36: 66.6 | D36: 40.95 | E36: 41.92 | F36: 97.5 | G36: 13.4 | H36: 86.2 | I36: 148 | J36: 18.1 | K36: 53.7 | T36: 142 | U36: 41.2
A37: 596.1 | B37: 33.3 | C37: 66.7 | D37: 39.42 | E37: 44.68 | F37: 85.4 | G37: 13.9 | H37: 84.3 | I37: 153 | J37: 22.1 | K37: 47.2 | T37: 235 | U37: 38.6
A38: 651.3 | B38: 33.6 | C38: 66.4 | D38: 37.73 | E38: 44.64 | F38: 102.7 | G38: 13.6 | H38: 89.9 | I38: 146 | J38: 20.4 | K38: 52.6 | T38: 210 | U38: 19.6
A39: 603.1 | B39: 33.7 | C39: 66.3 | D39: 38.54 | E39: 44.16 | F39: 94.9 | G39: 9.4 | H39: 82.2 | I39: 164 | J39: 18.5 | K39: 53.5 | T39: 190 | U39: 29.4
A40: 570.6 | B40: 36 | C40: 64 | D40: 40.99 | E40: 42.59 | F40: 101.5 | G40: 9.6 | H40: 83.4 | I40: 166 | J40: 19 | K40: 53.2 | T40: 223 | U40: 30.2
A41: 671.8 | B41: 35.1 | C41: 64.9 | D41: 37.77 | E41: 46.26 | F41: 99.2 | G41: 9.3 | H41: 85.8 | I41: 152 | J41: 21.7 | K41: 45.5 | T41: 227 | U41: 44.2
A42: 640.2 | B42: 33 | C42: 67 | D42: 37.83 | E42: 45.23 | F42: 98.1 | G42: 10.4 | H42: 89.5 | I42: 145 | J42: 20.6 | K42: 54.4 | T42: 182 | U42: 34.2
A43: 659.8 | B43: 35.4 | C43: 64.6 | D43: 40 | E43: 43.67 | F43: 85.7 | G43: 13.6 | H43: 86.2 | I43: 168 | J43: 20.9 | K43: 46.2 | T43: 153 | U43: 35.6
... A81: 636.9 | B81: 35.1 | C81: 64.9 | D81: 38.95 | E81: 43.94 | F81: 85.2 | G81: 19.7 | H81: 75.5 | I81: 161 | J81: 23.2 | K81: 52.2 | T81: 152 | U81: 42.1
A82: 637.5 | B82: 33.2 | C82: 66.8 | D82: 38.73 | E82: 43.75 | F82: 93.9 | G82: 20.5 | H82: 74.9 | Q82: 172 | R82: 32.5
A83: 590.5 | B83: 35 | C83: 65 | D83: 39.92 | E83: 43.19 | F83: 89.4 | G83: 21.4 | H83: 72.7 | I83: 164 | J83: 18.8 | K83: 49.9 | T83: 143 | U83: 30.2
A84: 677.9 | B84: 33.3 | C84: 66.7 | D84: 41.34 | E84: 41.21 | F84: 92.7 | G84: 18.2 | H84: 73.2 | I84: 145 | J84: 21.3 | K84: 50.4 | T84: 216 | U84: 40
A85: 664.4 | B85: 34.8 | C85: 65.2 | D85: 39.78 | E85: 42.75 | F85: 89 | G85: 18.5 | H85: 70.2 | I85: 157 | J85: 21.3 | K85: 47.3 | T85: 236 | U85: 42.3
A86: 587.2 | B86: 32.9 | C86: 67.1 | D86: 41.43 | E86: 40.79 | F86: 94.8 | G86: 11.9 | H86: 88.7 | I86: 174 | J86: 20.4 | K86: 53.3 | T86: 216 | U86: 32.2
A87: 640 | B87: 32.6 | C87: 67.4 | D87: 39.56 | E87: 42.59 | F87: 90.6 | G87: 10.1 | H87: 89.6 | I87: 140 | J87: 24 | K87: 51.8 | T87: 223 | U87: 23.8
A88: 595.3 | B88: 32.5 | C88: 67.5 | D88: 42.18 | E88: 40.88 | F88: 104.1 | G88: 11.6 | H88: 83 | I88: 143 | J88: 21 | K88: 52.9 | T88: 211 | U88: 16.5
A89: 566 | B89: 36 | C89: 64 | D89: 40.46 | E89: 41.91 | F89: 97.5 | G89: 9.4 | H89: 86.8 | I89: 148 | J89: 22.3 | K89: 53.2 | T89: 220 | U89: 31.6
A90: 659.1 | B90: 32 | C90: 68 | D90: 39.73 | E90: 43.58 | F90: 87 | G90: 10.8 | H90: 82.7 | I90: 169 | J90: 19.9 | K90: 52.9 | T90: 229 | U90: 28
A91: 588.7 | B91: 32.5 | C91: 67.5 | D91: 41.77 | E91: 41.49 | F91: 92.2 | G91: 13.8 | H91: 85 | I91: 155 | J91: 20.7 | K91: 47.1 | T91: 177 | U91: 26.1
A92: 633.8 | B92: 33.8 | C92: 66.2 | D92: 41.05 | E92: 40.35 | F92: 90.7 | G92: 10.8 | H92: 80.6 | I92: 144 | J92: 21.1 | K92: 47.7 | T92: 224 | U92: 15.4
A93: 617.8 | B93: 36.4 | C93: 63.6 | D93: 38.52 | E93: 44.07 | F93: 101.1 | G93: 9.6 | H93: 82.7 | I93: 141 | J93: 19.8 | K93: 52.7 | T93: 192 | U93: 25.4
A94: 647.2 | B94: 34.1 | C94: 65.9 | D94: 39.19 | E94: 42.74 | F94: 100.7 | G94: 14 | H94: 85.4 | I94: 174 | J94: 18.5 | K94: 48.7 | T94: 163 | U94: 20.9
...
